Workbook

Sheet FILL ME
A1: Fill out the highlighted info to autofill sample template
A3: Project (e.g., WWS, NIFA) | B3: WWS
A4: Study Code (e.g., SONDE, BDRK, SSFLAT) | B4: SSFLAT
A5: Site Codes (separated by commas) | B5: CMP, ALD
A6: Samples per Site | B6: 24
A7: Sample Start Date | B7: 46100
A8: Sample Type (choose one) | B8: ISCO
A9: Sample ID Type (choose one) | B9: Bottle Number
A10: For ISCO Samples only
A11: Sample Start Time | B11: 0.41666667
A12: Time Interval (Hours) | B12: 0.083333333
A13: Start Bottle Number | B13: 1
A15: Number of Sites (autofilled) | B15: =COUNTA(_xlfn.TEXTSPLIT('FILL ME'!$B$5, ", ")) -> 2
A17: DIRECTIONS
A18: 1. Fill out the information above to auto populate the sample IDs which will autopopulate the datasheets
A19: 2. If collecting grab samples, fill out times manually to fully populate datasheets after collection.
A20: 3. Print out the Bottle Number data sheet in landscape using "fit all columns on one page".
A21: 4. Print out the ISCO Bottle Weight data sheet in portrait (if applicable) using "fit all columns on one page".
A22: 5. Print out the Filter Weight data sheet in portrait (if applicable) using "fit all columns on one page".

Sheet Label IDs
A1: Sample Type | B1: Project | C1: Study | D1: Start Date | E1: Collect DateTime | F1: Collect Time | G1: ISCO Bottle # | H1: Site | I1: ISCO Bottle ID | J1: Sample ID (with Bottle #) | K1: Sample ID (with Time)
A2: ='FILL ME'!$B$8 -> ISCO | B2: =IF('FILL ME'!$B$3 = "", "", 'FILL ME'!$B$3) -> WWS | C2: =IF('FILL ME'!$B$4 = "", "", 'FILL ME'!$B$4) -> SSFLAT | D2: =TEXT('FILL ME'!$B$7,"yyyymmdd") -> 20260319 | E2: ='FILL ME'!$B$7 + 'FILL ME'!$B$11 + ('FILL ME'!$B$12 * (G2-'FILL ME'!$B$13)) -> 46100.417 | F2: =IF(A2="Grab","",TEXT(E2,"hh:mm")) -> 10:00 | G2: {=MOD(_xlfn.SEQUENCE('FILL ME'!B6*'FILL ME'!B15,,0),'FILL ME'!B6) + 'FILL ME'!B13} -> 1 | H2: {=_xlfn.LET( _xlpm.items, _xlfn.TEXTSPLIT('FILL ME'!$B$5, ", "), _xlpm.x, 'FILL ME'!$B$6, INDEX(_xlpm.items, ROUNDUP(_xlfn.SEQUENCE(COUNTA(_xlpm.items)*_xlpm.x)/_xlpm.x, 0)) )} -> CMP | I2: =CONCATENATE(H2,"_",TEXT(G2,"00")) -> CMP_01 | J2: =CONCATENATE(C2,"_", H2,"_",D2,"_",TEXT(G2,"00")) -> SSFLAT_CMP_20260319_01 | K2: =CONCATENATE(C2,"_", H2,"_",TEXT(E2, "yyyymmdd"),"_",TEXT(F2, "hhmm")) -> SSFLAT_CMP_20260319_1000
A3: ='FILL ME'!$B$8 -> ISCO | B3: =IF('FILL ME'!$B$3 = "", "", 'FILL ME'!$B$3) -> WWS | C3: =IF('FILL ME'!$B$4 = "", "", 'FILL ME'!$B$4) -> SSFLAT | D3: =TEXT('FILL ME'!$B$7,"yyyymmdd") -> 20260319 | E3: ='FILL ME'!$B$7 + 'FILL ME'!$B$11 + ('FILL ME'!$B$12 * (G3-'FILL ME'!$B$13)) -> 46100.5 | F3: =IF(A3="Grab","",TEXT(E3,"hh:mm")) -> 12:00 | G3: 2 | H3: CMP | I3: =CONCATENATE(H3,"_",TEXT(G3,"00")) -> CMP_02 | J3: =CONCATENATE(C3,"_", H3,"_",D3,"_",TEXT(G3,"00")) -> SSFLAT_CMP_20260319_02 | K3: =CONCATENATE(C3,"_", H3,"_",TEXT(E3, "yyyymmdd"),"_",TEXT(F3, "hhmm")) -> SSFLAT_CMP_20260319_1200
A4: ='FILL ME'!$B$8 -> ISCO | B4: =IF('FILL ME'!$B$3 = "", "", 'FILL ME'!$B$3) -> WWS | C4: =IF('FILL ME'!$B$4 = "", "", 'FILL ME'!$B$4) -> SSFLAT | D4: =TEXT('FILL ME'!$B$7,"yyyymmdd") -> 20260319 | E4: ='FILL ME'!$B$7 + 'FILL ME'!$B$11 + ('FILL ME'!$B$12 * (G4-'FILL ME'!$B$13)) -> 46100.583 | F4: =IF(A4="Grab","",TEXT(E4,"hh:mm")) -> 14:00 | G4: 3 | H4: CMP | I4: =CONCATENATE(H4,"_",TEXT(G4,"00")) -> CMP_03 | J4: =CONCATENATE(C4,"_", H4,"_",D4,"_",TEXT(G4,"00")) -> SSFLAT_CMP_20260319_03 | K4: =CONCATENATE(C4,"_", H4,"_",TEXT(E4, "yyyymmdd"),"_",TEXT(F4, "hhmm")) -> SSFLAT_CMP_20260319_1400
A5: ='FILL ME'!$B$8 -> ISCO | B5: =IF('FILL ME'!$B$3 = "", "", 'FILL ME'!$B$3) -> WWS | C5: =IF('FILL ME'!$B$4 = "", "", 'FILL ME'!$B$4) -> SSFLAT | D5: =TEXT('FILL ME'!$B$7,"yyyymmdd") -> 20260319 | E5: ='FILL ME'!$B$7 + 'FILL ME'!$B$11 + ('FILL ME'!$B$12 * (G5-'FILL ME'!$B$13)) -> 46100.667 | F5: =IF(A5="Grab","",TEXT(E5,"hh:mm")) -> 16:00 | G5: 4 | H5: CMP | I5: =CONCATENATE(H5,"_",TEXT(G5,"00")) -> CMP_04 | J5: =CONCATENATE(C5,"_", H5,"_",D5,"_",TEXT(G5,"00")) -> SSFLAT_CMP_20260319_04 | K5: =CONCATENATE(C5,"_", H5,"_",TEXT(E5, "yyyymmdd"),"_",TEXT(F5, "hhmm")) -> SSFLAT_CMP_20260319_1600
A6: ='FILL ME'!$B$8 -> ISCO | B6: =IF('FILL ME'!$B$3 = "", "", 'FILL ME'!$B$3) -> WWS | C6: =IF('FILL ME'!$B$4 = "", "", 'FILL ME'!$B$4) -> SSFLAT | D6: =TEXT('FILL ME'!$B$7,"yyyymmdd") -> 20260319 | E6: ='FILL ME'!$B$7 + 'FILL ME'!$B$11 + ('FILL ME'!$B$12 * (G6-'FILL ME'!$B$13)) -> 46100.75 | F6: =IF(A6="Grab","",TEXT(E6,"hh:mm")) -> 18:00 | G6: 5 | H6: CMP | I6: =CONCATENATE(H6,"_",TEXT(G6,"00")) -> CMP_05 | J6: =CONCATENATE(C6,"_", H6,"_",D6,"_",TEXT(G6,"00")) -> SSFLAT_CMP_20260319_05 | K6: =CONCATENATE(C6,"_", H6,"_",TEXT(E6, "yyyymmdd"),"_",TEXT(F6, "hhmm")) -> SSFLAT_CMP_20260319_1800
A7: ='FILL ME'!$B$8 -> ISCO | B7: =IF('FILL ME'!$B$3 = "", "", 'FILL ME'!$B$3) -> WWS | C7: =IF('FILL ME'!$B$4 = "", "", 'FILL ME'!$B$4) -> SSFLAT | D7: =TEXT('FILL ME'!$B$7,"yyyymmdd") -> 20260319 | E7: ='FILL ME'!$B$7 + 'FILL ME'!$B$11 + ('FILL ME'!$B$12 * (G7-'FILL ME'!$B$13)) -> 46100.833 | F7: =IF(A7="Grab","",TEXT(E7,"hh:mm")) -> 20:00 | G7: 6 | H7: CMP | I7: =CONCATENATE(H7,"_",TEXT(G7,"00")) -> CMP_06 | J7: =CONCATENATE(C7,"_", H7,"_",D7,"_",TEXT(G7,"00")) -> SSFLAT_CMP_20260319_06 | K7: =CONCATENATE(C7,"_", H7,"_",TEXT(E7, "yyyymmdd"),"_",TEXT(F7, "hhmm")) -> SSFLAT_CMP_20260319_2000
A8: ='FILL ME'!$B$8 -> ISCO | B8: =IF('FILL ME'!$B$3 = "", "", 'FILL ME'!$B$3) -> WWS | C8: =IF('FILL ME'!$B$4 = "", "", 'FILL ME'!$B$4) -> SSFLAT | D8: =TEXT('FILL ME'!$B$7,"yyyymmdd") -> 20260319 | E8: ='FILL ME'!$B$7 + 'FILL ME'!$B$11 + ('FILL ME'!$B$12 * (G8-'FILL ME'!$B$13)) -> 46100.917 | F8: =IF(A8="Grab","",TEXT(E8,"hh:mm")) -> 22:00 | G8: 7 | H8: CMP | I8: =CONCATENATE(H8,"_",TEXT(G8,"00")) -> CMP_07 | J8: =CONCATENATE(C8,"_", H8,"_",D8,"_",TEXT(G8,"00")) -> SSFLAT_CMP_20260319_07 | K8: =CONCATENATE(C8,"_", H8,"_",TEXT(E8, "yyyymmdd"),"_",TEXT(F8, "hhmm")) -> SSFLAT_CMP_20260319_2200
A9: ='FILL ME'!$B$8 -> ISCO | B9: =IF('FILL ME'!$B$3 = "", "", 'FILL ME'!$B$3) -> WWS | C9: =IF('FILL ME'!$B$4 = "", "", 'FILL ME'!$B$4) -> SSFLAT | D9: =TEXT('FILL ME'!$B$7,"yyyymmdd") -> 20260319 | E9: ='FILL ME'!$B$7 + 'FILL ME'!$B$11 + ('FILL ME'!$B$12 * (G9-'FILL ME'!$B$13)) -> 46101 | F9: =IF(A9="Grab","",TEXT(E9,"hh:mm")) -> 00:00 | G9: 8 | H9: CMP | I9: =CONCATENATE(H9,"_",TEXT(G9,"00")) -> CMP_08 | J9: =CONCATENATE(C9,"_", H9,"_",D9,"_",TEXT(G9,"00")) -> SSFLAT_CMP_20260319_08 | K9: =CONCATENATE(C9,"_", H9,"_",TEXT(E9, "yyyymmdd"),"_",TEXT(F9, "hhmm")) -> SSFLAT_CMP_20260320_0000
A10: ='FILL ME'!$B$8 -> ISCO | B10: =IF('FILL ME'!$B$3 = "", "", 'FILL ME'!$B$3) -> WWS | C10: =IF('FILL ME'!$B$4 = "", "", 'FILL ME'!$B$4) -> SSFLAT | D10: =TEXT('FILL ME'!$B$7,"yyyymmdd") -> 20260319 | E10: ='FILL ME'!$B$7 + 'FILL ME'!$B$11 + ('FILL ME'!$B$12 * (G10-'FILL ME'!$B$13)) -> 46101.083 | F10: =IF(A10="Grab","",TEXT(E10,"hh:mm")) -> 02:00 | G10: 9 | H10: CMP | I10: =CONCATENATE(H10,"_",TEXT(G10,"00")) -> CMP_09 | J10: =CONCATENATE(C10,"_", H10,"_",D10,"_",TEXT(G10,"00")) -> SSFLAT_CMP_20260319_09 | K10: =CONCATENATE(C10,"_", H10,"_",TEXT(E10, "yyyymmdd"),"_",TEXT(F10, "hhmm")) -> SSFLAT_CMP_20260320_0200
A11: ='FILL ME'!$B$8 -> ISCO | B11: =IF('FILL ME'!$B$3 = "", "", 'FILL ME'!$B$3) -> WWS | C11: =IF('FILL ME'!$B$4 = "", "", 'FILL ME'!$B$4) -> SSFLAT | D11: =TEXT('FILL ME'!$B$7,"yyyymmdd") -> 20260319 | E11: ='FILL ME'!$B$7 + 'FILL ME'!$B$11 + ('FILL ME'!$B$12 * (G11-'FILL ME'!$B$13)) -> 46101.167 | F11: =IF(A11="Grab","",TEXT(E11,"hh:mm")) -> 04:00 | G11: 10 | H11: CMP | I11: =CONCATENATE(H11,"_",TEXT(G11,"00")) -> CMP_10 | J11: =CONCATENATE(C11,"_", H11,"_",D11,"_",TEXT(G11,"00")) -> SSFLAT_CMP_20260319_10 | K11: =CONCATENATE(C11,"_", H11,"_",TEXT(E11, "yyyymmdd"),"_",TEXT(F11, "hhmm")) -> SSFLAT_CMP_20260320_0400
A12: ='FILL ME'!$B$8 -> ISCO | B12: =IF('FILL ME'!$B$3 = "", "", 'FILL ME'!$B$3) -> WWS | C12: =IF('FILL ME'!$B$4 = "", "", 'FILL ME'!$B$4) -> SSFLAT | D12: =TEXT('FILL ME'!$B$7,"yyyymmdd") -> 20260319 | E12: ='FILL ME'!$B$7 + 'FILL ME'!$B$11 + ('FILL ME'!$B$12 * (G12-'FILL ME'!$B$13)) -> 46101.25 | F12: =IF(A12="Grab","",TEXT(E12,"hh:mm")) -> 06:00 | G12: 11 | H12: CMP | I12: =CONCATENATE(H12,"_",TEXT(G12,"00")) -> CMP_11 | J12: =CONCATENATE(C12,"_", H12,"_",D12,"_",TEXT(G12,"00")) -> SSFLAT_CMP_20260319_11 | K12: =CONCATENATE(C12,"_", H12,"_",TEXT(E12, "yyyymmdd"),"_",TEXT(F12, "hhmm")) -> SSFLAT_CMP_20260320_0600
A13: ='FILL ME'!$B$8 -> ISCO | B13: =IF('FILL ME'!$B$3 = "", "", 'FILL ME'!$B$3) -> WWS | C13: =IF('FILL ME'!$B$4 = "", "", 'FILL ME'!$B$4) -> SSFLAT | D13: =TEXT('FILL ME'!$B$7,"yyyymmdd") -> 20260319 | E13: ='FILL ME'!$B$7 + 'FILL ME'!$B$11 + ('FILL ME'!$B$12 * (G13-'FILL ME'!$B$13)) -> 46101.333 | F13: =IF(A13="Grab","",TEXT(E13,"hh:mm")) -> 08:00 | G13: 12 | H13: CMP | I13: =CONCATENATE(H13,"_",TEXT(G13,"00")) -> CMP_12 | J13: =CONCATENATE(C13,"_", H13,"_",D13,"_",TEXT(G13,"00")) -> SSFLAT_CMP_20260319_12 | K13: =CONCATENATE(C13,"_", H13,"_",TEXT(E13, "yyyymmdd"),"_",TEXT(F13, "hhmm")) -> SSFLAT_CMP_20260320_0800
A14: ='FILL ME'!$B$8 -> ISCO | B14: =IF('FILL ME'!$B$3 = "", "", 'FILL ME'!$B$3) -> WWS | C14: =IF('FILL ME'!$B$4 = "", "", 'FILL ME'!$B$4) -> SSFLAT | D14: =TEXT('FILL ME'!$B$7,"yyyymmdd") -> 20260319 | E14: ='FILL ME'!$B$7 + 'FILL ME'!$B$11 + ('FILL ME'!$B$12 * (G14-'FILL ME'!$B$13)) -> 46101.417 | F14: =IF(A14="Grab","",TEXT(E14,"hh:mm")) -> 10:00 | G14: 13 | H14: CMP | I14: =CONCATENATE(H14,"_",TEXT(G14,"00")) -> CMP_13 | J14: =CONCATENATE(C14,"_", H14,"_",D14,"_",TEXT(G14,"00")) -> SSFLAT_CMP_20260319_13 | K14: =CONCATENATE(C14,"_", H14,"_",TEXT(E14, "yyyymmdd"),"_",TEXT(F14, "hhmm")) -> SSFLAT_CMP_20260320_1000
... A49: ='FILL ME'!$B$8 -> ISCO | B49: =IF('FILL ME'!$B$3 = "", "", 'FILL ME'!$B$3) -> WWS | C49: =IF('FILL ME'!$B$4 = "", "", 'FILL ME'!$B$4) -> SSFLAT | D49: =TEXT('FILL ME'!$B$7,"yyyymmdd") -> 20260319 | E49: ='FILL ME'!$B$7 + 'FILL ME'!$B$11 + ('FILL ME'!$B$12 * (G49-'FILL ME'!$B$13)) -> 46102.333 | F49: =IF(A49="Grab","",TEXT(E49,"hh:mm")) -> 08:00 | G49: 24 | H49: ALD | I49: =CONCATENATE(H49,"_",TEXT(G49,"00")) -> ALD_24 | J49: =CONCATENATE(C49,"_", H49,"_",D49,"_",TEXT(G49,"00")) -> SSFLAT_ALD_20260319_24 | K49: =CONCATENATE(C49,"_", H49,"_",TEXT(E49, "yyyymmdd"),"_",TEXT(F49, "hhmm")) -> SSFLAT_ALD_20260321_0800
A50: ='FILL ME'!$B$8 -> ISCO | B50: =IF('FILL ME'!$B$3 = "", "", 'FILL ME'!$B$3) -> WWS | C50: =IF('FILL ME'!$B$4 = "", "", 'FILL ME'!$B$4) -> SSFLAT | D50: =TEXT('FILL ME'!$B$7,"yyyymmdd") -> 20260319 | E50: ='FILL ME'!$B$7 + 'FILL ME'!$B$11 + ('FILL ME'!$B$12 * (G50-'FILL ME'!$B$13)) -> 46100.333 | F50: =IF(A50="Grab","",TEXT(E50,"hh:mm")) -> 08:00 | I50: =CONCATENATE(H50,"_",TEXT(G50,"00")) -> _00 | J50: =CONCATENATE(C50,"_", H50,"_",D50,"_",TEXT(G50,"00")) -> SSFLAT__20260319_00 | K50: =CONCATENATE(C50,"_", H50,"_",TEXT(E50, "yyyymmdd"),"_",TEXT(F50, "hhmm")) -> SSFLAT__20260319_0800
A51: ='FILL ME'!$B$8 -> ISCO | B51: =IF('FILL ME'!$B$3 = "", "", 'FILL ME'!$B$3) -> WWS | C51: =IF('FILL ME'!$B$4 = "", "", 'FILL ME'!$B$4) -> SSFLAT | D51: =TEXT('FILL ME'!$B$7,"yyyymmdd") -> 20260319 | E51: ='FILL ME'!$B$7 + 'FILL ME'!$B$11 + ('FILL ME'!$B$12 * (G51-'FILL ME'!$B$13)) -> 46100.333 | F51: =IF(A51="Grab","",TEXT(E51,"hh:mm")) -> 08:00 | I51: =CONCATENATE(H51,"_",TEXT(G51,"00")) -> _00 | J51: =CONCATENATE(C51,"_", H51,"_",D51,"_",TEXT(G51,"00")) -> SSFLAT__20260319_00 | K51: =CONCATENATE(C51,"_", H51,"_",TEXT(E51, "yyyymmdd"),"_",TEXT(F51, "hhmm")) -> SSFLAT__20260319_0800
A52: ='FILL ME'!$B$8 -> ISCO | B52: =IF('FILL ME'!$B$3 = "", "", 'FILL ME'!$B$3) -> WWS | C52: =IF('FILL ME'!$B$4 = "", "", 'FILL ME'!$B$4) -> SSFLAT | D52: =TEXT('FILL ME'!$B$7,"yyyymmdd") -> 20260319 | E52: ='FILL ME'!$B$7 + 'FILL ME'!$B$11 + ('FILL ME'!$B$12 * (G52-'FILL ME'!$B$13)) -> 46100.333 | F52: =IF(A52="Grab","",TEXT(E52,"hh:mm")) -> 08:00 | I52: =CONCATENATE(H52,"_",TEXT(G52,"00")) -> _00 | J52: =CONCATENATE(C52,"_", H52,"_",D52,"_",TEXT(G52,"00")) -> SSFLAT__20260319_00 | K52: =CONCATENATE(C52,"_", H52,"_",TEXT(E52, "yyyymmdd"),"_",TEXT(F52, "hhmm")) -> SSFLAT__20260319_0800
A53: ='FILL ME'!$B$8 -> ISCO | B53: =IF('FILL ME'!$B$3 = "", "", 'FILL ME'!$B$3) -> WWS | C53: =IF('FILL ME'!$B$4 = "", "", 'FILL ME'!$B$4) -> SSFLAT | D53: =TEXT('FILL ME'!$B$7,"yyyymmdd") -> 20260319 | E53: ='FILL ME'!$B$7 + 'FILL ME'!$B$11 + ('FILL ME'!$B$12 * (G53-'FILL ME'!$B$13)) -> 46100.333 | F53: =IF(A53="Grab","",TEXT(E53,"hh:mm")) -> 08:00 | I53: =CONCATENATE(H53,"_",TEXT(G53,"00")) -> _00 | J53: =CONCATENATE(C53,"_", H53,"_",D53,"_",TEXT(G53,"00")) -> SSFLAT__20260319_00 | K53: =CONCATENATE(C53,"_", H53,"_",TEXT(E53, "yyyymmdd"),"_",TEXT(F53, "hhmm")) -> SSFLAT__20260319_0800
A54: ='FILL ME'!$B$8 -> ISCO | B54: =IF('FILL ME'!$B$3 = "", "", 'FILL ME'!$B$3) -> WWS | C54: =IF('FILL ME'!$B$4 = "", "", 'FILL ME'!$B$4) -> SSFLAT | D54: =TEXT('FILL ME'!$B$7,"yyyymmdd") -> 20260319 | E54: ='FILL ME'!$B$7 + 'FILL ME'!$B$11 + ('FILL ME'!$B$12 * (G54-'FILL ME'!$B$13)) -> 46100.333 | F54: =IF(A54="Grab","",TEXT(E54,"hh:mm")) -> 08:00 | I54: =CONCATENATE(H54,"_",TEXT(G54,"00")) -> _00 | J54: =CONCATENATE(C54,"_", H54,"_",D54,"_",TEXT(G54,"00")) -> SSFLAT__20260319_00 | K54: =CONCATENATE(C54,"_", H54,"_",TEXT(E54, "yyyymmdd"),"_",TEXT(F54, "hhmm")) -> SSFLAT__20260319_0800
A55: ='FILL ME'!$B$8 -> ISCO | B55: =IF('FILL ME'!$B$3 = "", "", 'FILL ME'!$B$3) -> WWS | C55: =IF('FILL ME'!$B$4 = "", "", 'FILL ME'!$B$4) -> SSFLAT | D55: =TEXT('FILL ME'!$B$7,"yyyymmdd") -> 20260319 | E55: ='FILL ME'!$B$7 + 'FILL ME'!$B$11 + ('FILL ME'!$B$12 * (G55-'FILL ME'!$B$13)) -> 46100.333 | F55: =IF(A55="Grab","",TEXT(E55,"hh:mm")) -> 08:00 | I55: =CONCATENATE(H55,"_",TEXT(G55,"00")) -> _00 | J55: =CONCATENATE(C55,"_", H55,"_",D55,"_",TEXT(G55,"00")) -> SSFLAT__20260319_00 | K55: =CONCATENATE(C55,"_", H55,"_",TEXT(E55, "yyyymmdd"),"_",TEXT(F55, "hhmm")) -> SSFLAT__20260319_0800
A56: ='FILL ME'!$B$8 -> ISCO | B56: =IF('FILL ME'!$B$3 = "", "", 'FILL ME'!$B$3) -> WWS | C56: =IF('FILL ME'!$B$4 = "", "", 'FILL ME'!$B$4) -> SSFLAT | D56: =TEXT('FILL ME'!$B$7,"yyyymmdd") -> 20260319 | E56: ='FILL ME'!$B$7 + 'FILL ME'!$B$11 + ('FILL ME'!$B$12 * (G56-'FILL ME'!$B$13)) -> 46100.333 | F56: =IF(A56="Grab","",TEXT(E56,"hh:mm")) -> 08:00 | I56: =CONCATENATE(H56,"_",TEXT(G56,"00")) -> _00 | J56: =CONCATENATE(C56,"_", H56,"_",D56,"_",TEXT(G56,"00")) -> SSFLAT__20260319_00 | K56: =CONCATENATE(C56,"_", H56,"_",TEXT(E56, "yyyymmdd"),"_",TEXT(F56, "hhmm")) -> SSFLAT__20260319_0800
A57: ='FILL ME'!$B$8 -> ISCO | B57: =IF('FILL ME'!$B$3 = "", "", 'FILL ME'!$B$3) -> WWS | C57: =IF('FILL ME'!$B$4 = "", "", 'FILL ME'!$B$4) -> SSFLAT | D57: =TEXT('FILL ME'!$B$7,"yyyymmdd") -> 20260319 | E57: ='FILL ME'!$B$7 + 'FILL ME'!$B$11 + ('FILL ME'!$B$12 * (G57-'FILL ME'!$B$13)) -> 46100.333 | F57: =IF(A57="Grab","",TEXT(E57,"hh:mm")) -> 08:00 | I57: =CONCATENATE(H57,"_",TEXT(G57,"00")) -> _00 | J57: =CONCATENATE(C57,"_", H57,"_",D57,"_",TEXT(G57,"00")) -> SSFLAT__20260319_00 | K57: =CONCATENATE(C57,"_", H57,"_",TEXT(E57, "yyyymmdd"),"_",TEXT(F57, "hhmm")) -> SSFLAT__20260319_0800
A58: ='FILL ME'!$B$8 -> ISCO | B58: =IF('FILL ME'!$B$3 = "", "", 'FILL ME'!$B$3) -> WWS | C58: =IF('FILL ME'!$B$4 = "", "", 'FILL ME'!$B$4) -> SSFLAT | D58: =TEXT('FILL ME'!$B$7,"yyyymmdd") -> 20260319 | E58: ='FILL ME'!$B$7 + 'FILL ME'!$B$11 + ('FILL ME'!$B$12 * (G58-'FILL ME'!$B$13)) -> 46100.333 | F58: =IF(A58="Grab","",TEXT(E58,"hh:mm")) -> 08:00 | I58: =CONCATENATE(H58,"_",TEXT(G58,"00")) -> _00 | J58: =CONCATENATE(C58,"_", H58,"_",D58,"_",TEXT(G58,"00")) -> SSFLAT__20260319_00 | K58: =CONCATENATE(C58,"_", H58,"_",TEXT(E58, "yyyymmdd"),"_",TEXT(F58, "hhmm")) -> SSFLAT__20260319_0800
A59: ='FILL ME'!$B$8 -> ISCO | B59: =IF('FILL ME'!$B$3 = "", "", 'FILL ME'!$B$3) -> WWS | C59: =IF('FILL ME'!$B$4 = "", "", 'FILL ME'!$B$4) -> SSFLAT | D59: =TEXT('FILL ME'!$B$7,"yyyymmdd") -> 20260319 | E59: ='FILL ME'!$B$7 + 'FILL ME'!$B$11 + ('FILL ME'!$B$12 * (G59-'FILL ME'!$B$13)) -> 46100.333 | F59: =IF(A59="Grab","",TEXT(E59,"hh:mm")) -> 08:00 | I59: =CONCATENATE(H59,"_",TEXT(G59,"00")) -> _00 | J59: =CONCATENATE(C59,"_", H59,"_",D59,"_",TEXT(G59,"00")) -> SSFLAT__20260319_00 | K59: =CONCATENATE(C59,"_", H59,"_",TEXT(E59, "yyyymmdd"),"_",TEXT(F59, "hhmm")) -> SSFLAT__20260319_0800
A60: ='FILL ME'!$B$8 -> ISCO | B60: =IF('FILL ME'!$B$3 = "", "", 'FILL ME'!$B$3) -> WWS | C60: =IF('FILL ME'!$B$4 = "", "", 'FILL ME'!$B$4) -> SSFLAT | D60: =TEXT('FILL ME'!$B$7,"yyyymmdd") -> 20260319 | E60: ='FILL ME'!$B$7 + 'FILL ME'!$B$11 + ('FILL ME'!$B$12 * (G60-'FILL ME'!$B$13)) -> 46100.333 | F60: =IF(A60="Grab","",TEXT(E60,"hh:mm")) -> 08:00 | I60: =CONCATENATE(H60,"_",TEXT(G60,"00")) -> _00 | J60: =CONCATENATE(C60,"_", H60,"_",D60,"_",TEXT(G60,"00")) -> SSFLAT__20260319_00 | K60: =CONCATENATE(C60,"_", H60,"_",TEXT(E60, "yyyymmdd"),"_",TEXT(F60, "hhmm")) -> SSFLAT__20260319_0800
A61: ='FILL ME'!$B$8 -> ISCO | B61: =IF('FILL ME'!$B$3 = "", "", 'FILL ME'!$B$3) -> WWS | C61: =IF('FILL ME'!$B$4 = "", "", 'FILL ME'!$B$4) -> SSFLAT | D61: =TEXT('FILL ME'!$B$7,"yyyymmdd") -> 20260319 | E61: ='FILL ME'!$B$7 + 'FILL ME'!$B$11 + ('FILL ME'!$B$12 * (G61-'FILL ME'!$B$13)) -> 46100.333 | F61: =IF(A61="Grab","",TEXT(E61,"hh:mm")) -> 08:00 | I61: =CONCATENATE(H61,"_",TEXT(G61,"00")) -> _00 | J61: =CONCATENATE(C61,"_", H61,"_",D61,"_",TEXT(G61,"00")) -> SSFLAT__20260319_00 | K61: =CONCATENATE(C61,"_", H61,"_",TEXT(E61, "yyyymmdd"),"_",TEXT(F61, "hhmm")) -> SSFLAT__20260319_0800
B62: =IF('FILL ME'!$B$3 = "", "", 'FILL ME'!$B$3) -> WWS | C62: =IF('FILL ME'!$B$4 = "", "", 'FILL ME'!$B$4) -> SSFLAT | D62: =TEXT('FILL ME'!$B$7,"yyyymmdd") -> 20260319 | E62: ='FILL ME'!$B$7 + 'FILL ME'!$B$11 + ('FILL ME'!$B$12 * (G62-'FILL ME'!$B$13)) -> 46100.333 | F62: =IF(A62="Grab","",TEXT(E62,"hh:mm")) -> 08:00 | I62: =CONCATENATE(H62,"_",TEXT(G62,"00")) -> _00 | J62: =CONCATENATE(C62,"_", H62,"_",D62,"_",TEXT(G62,"00")) -> SSFLAT__20260319_00 | K62: =CONCATENATE(C62,"_", H62,"_",TEXT(E62, "yyyymmdd"),"_",TEXT(F62, "hhmm")) -> SSFLAT__20260319_0800
B63: =IF('FILL ME'!$B$3 = "", "", 'FILL ME'!$B$3) -> WWS | C63: =IF('FILL ME'!$B$4 = "", "", 'FILL ME'!$B$4) -> SSFLAT | D63: =TEXT('FILL ME'!$B$7,"yyyymmdd") -> 20260319 | E63: ='FILL ME'!$B$7 + 'FILL ME'!$B$11 + ('FILL ME'!$B$12 * (G63-'FILL ME'!$B$13)) -> 46100.333 | F63: =IF(A63="Grab","",TEXT(E63,"hh:mm")) -> 08:00 | I63: =CONCATENATE(H63,"_",TEXT(G63,"00")) -> _00 | J63: =CONCATENATE(C63,"_", H63,"_",D63,"_",TEXT(G63,"00")) -> SSFLAT__20260319_00 | K63: =CONCATENATE(C63,"_", H63,"_",TEXT(E63, "yyyymmdd"),"_",TEXT(F63, "hhmm")) -> SSFLAT__20260319_0800
B64: =IF('FILL ME'!$B$3 = "", "", 'FILL ME'!$B$3) -> WWS | C64: =IF('FILL ME'!$B$4 = "", "", 'FILL ME'!$B$4) -> SSFLAT | D64: =TEXT('FILL ME'!$B$7,"yyyymmdd") -> 20260319 | E64: ='FILL ME'!$B$7 + 'FILL ME'!$B$11 + ('FILL ME'!$B$12 * (G64-'FILL ME'!$B$13)) -> 46100.333 | F64: =IF(A64="Grab","",TEXT(E64,"hh:mm")) -> 08:00 | I64: =CONCATENATE(H64,"_",TEXT(G64,"00")) -> _00 | J64: =CONCATENATE(C64,"_", H64,"_",D64,"_",TEXT(G64,"00")) -> SSFLAT__20260319_00 | K64: =CONCATENATE(C64,"_", H64,"_",TEXT(E64, "yyyymmdd"),"_",TEXT(F64, "hhmm")) -> SSFLAT__20260319_0800
B65: =IF('FILL ME'!$B$3 = "", "", 'FILL ME'!$B$3) -> WWS | C65: =IF('FILL ME'!$B$4 = "", "", 'FILL ME'!$B$4) -> SSFLAT | D65: =TEXT('FILL ME'!$B$7,"yyyymmdd") -> 20260319 | E65: ='FILL ME'!$B$7 + 'FILL ME'!$B$11 + ('FILL ME'!$B$12 * (G65-'FILL ME'!$B$13)) -> 46100.333 | F65: =IF(A65="Grab","",TEXT(E65,"hh:mm")) -> 08:00 | I65: =CONCATENATE(H65,"_",TEXT(G65,"00")) -> _00 | J65: =CONCATENATE(C65,"_", H65,"_",D65,"_",TEXT(G65,"00")) -> SSFLAT__20260319_00 | K65: =CONCATENATE(C65,"_", H65,"_",TEXT(E65, "yyyymmdd"),"_",TEXT(F65, "hhmm")) -> SSFLAT__20260319_0800
B66: =IF('FILL ME'!$B$3 = "", "", 'FILL ME'!$B$3) -> WWS | C66: =IF('FILL ME'!$B$4 = "", "", 'FILL ME'!$B$4) -> SSFLAT | D66: =TEXT('FILL ME'!$B$7,"yyyymmdd") -> 20260319 | E66: ='FILL ME'!$B$7 + 'FILL ME'!$B$11 + ('FILL ME'!$B$12 * (G66-'FILL ME'!$B$13)) -> 46100.333 | F66: =IF(A66="Grab","",TEXT(E66,"hh:mm")) -> 08:00 | I66: =CONCATENATE(H66,"_",TEXT(G66,"00")) -> _00 | J66: =CONCATENATE(C66,"_", H66,"_",D66,"_",TEXT(G66,"00")) -> SSFLAT__20260319_00 | K66: =CONCATENATE(C66,"_", H66,"_",TEXT(E66, "yyyymmdd"),"_",TEXT(F66, "hhmm")) -> SSFLAT__20260319_0800
B67: =IF('FILL ME'!$B$3 = "", "", 'FILL ME'!$B$3) -> WWS | C67: =IF('FILL ME'!$B$4 = "", "", 'FILL ME'!$B$4) -> SSFLAT | D67: =TEXT('FILL ME'!$B$7,"yyyymmdd") -> 20260319 | E67: ='FILL ME'!$B$7 + 'FILL ME'!$B$11 + ('FILL ME'!$B$12 * (G67-'FILL ME'!$B$13)) -> 46100.333 | F67: =IF(A67="Grab","",TEXT(E67,"hh:mm")) -> 08:00 | I67: =CONCATENATE(H67,"_",TEXT(G67,"00")) -> _00 | J67: =CONCATENATE(C67,"_", H67,"_",D67,"_",TEXT(G67,"00")) -> SSFLAT__20260319_00 | K67: =CONCATENATE(C67,"_", H67,"_",TEXT(E67, "yyyymmdd"),"_",TEXT(F67, "hhmm")) -> SSFLAT__20260319_0800
B68: =IF('FILL ME'!$B$3 = "", "", 'FILL ME'!$B$3) -> WWS | C68: =IF('FILL ME'!$B$4 = "", "", 'FILL ME'!$B$4) -> SSFLAT | D68: =TEXT('FILL ME'!$B$7,"yyyymmdd") -> 20260319 | E68: ='FILL ME'!$B$7 + 'FILL ME'!$B$11 + ('FILL ME'!$B$12 * (G68-'FILL ME'!$B$13)) -> 46100.333 | F68: =IF(A68="Grab","",TEXT(E68,"hh:mm")) -> 08:00 | I68: =CONCATENATE(H68,"_",TEXT(G68,"00")) -> _00 | J68: =CONCATENATE(C68,"_", H68,"_",D68,"_",TEXT(G68,"00")) -> SSFLAT__20260319_00 | K68: =CONCATENATE(C68,"_", H68,"_",TEXT(E68, "yyyymmdd"),"_",TEXT(F68, "hhmm")) -> SSFLAT__20260319_0800
B69: =IF('FILL ME'!$B$3 = "", "", 'FILL ME'!$B$3) -> WWS | C69: =IF('FILL ME'!$B$4 = "", "", 'FILL ME'!$B$4) -> SSFLAT | D69: =TEXT('FILL ME'!$B$7,"yyyymmdd") -> 20260319 | E69: ='FILL ME'!$B$7 + 'FILL ME'!$B$11 + ('FILL ME'!$B$12 * (G69-'FILL ME'!$B$13)) -> 46100.333 | F69: =IF(A69="Grab","",TEXT(E69,"hh:mm")) -> 08:00 | I69: =CONCATENATE(H69,"_",TEXT(G69,"00")) -> _00 | J69: =CONCATENATE(C69,"_", H69,"_",D69,"_",TEXT(G69,"00")) -> SSFLAT__20260319_00 | K69: =CONCATENATE(C69,"_", H69,"_",TEXT(E69, "yyyymmdd"),"_",TEXT(F69, "hhmm")) -> SSFLAT__20260319_0800
B70: =IF('FILL ME'!$B$3 = "", "", 'FILL ME'!$B$3) -> WWS | C70: =IF('FILL ME'!$B$4 = "", "", 'FILL ME'!$B$4) -> SSFLAT | D70: =TEXT('FILL ME'!$B$7,"yyyymmdd") -> 20260319 | E70: ='FILL ME'!$B$7 + 'FILL ME'!$B$11 + ('FILL ME'!$B$12 * (G70-'FILL ME'!$B$13)) -> 46100.333 | F70: =IF(A70="Grab","",TEXT(E70,"hh:mm")) -> 08:00 | I70: =CONCATENATE(H70,"_",TEXT(G70,"00")) -> _00 | J70: =CONCATENATE(C70,"_", H70,"_",D70,"_",TEXT(G70,"00")) -> SSFLAT__20260319_00 | K70: =CONCATENATE(C70,"_", H70,"_",TEXT(E70, "yyyymmdd"),"_",TEXT(F70, "hhmm")) -> SSFLAT__20260319_0800
B71: =IF('FILL ME'!$B$3 = "", "", 'FILL ME'!$B$3) -> WWS | C71: =IF('FILL ME'!$B$4 = "", "", 'FILL ME'!$B$4) -> SSFLAT | D71: =TEXT('FILL ME'!$B$7,"yyyymmdd") -> 20260319 | E71: ='FILL ME'!$B$7 + 'FILL ME'!$B$11 + ('FILL ME'!$B$12 * (G71-'FILL ME'!$B$13)) -> 46100.333 | F71: =IF(A71="Grab","",TEXT(E71,"hh:mm")) -> 08:00 | I71: =CONCATENATE(H71,"_",TEXT(G71,"00")) -> _00 | J71: =CONCATENATE(C71,"_", H71,"_",D71,"_",TEXT(G71,"00")) -> SSFLAT__20260319_00 | K71: =CONCATENATE(C71,"_", H71,"_",TEXT(E71, "yyyymmdd"),"_",TEXT(F71, "hhmm")) -> SSFLAT__20260319_0800
B72: =IF('FILL ME'!$B$3 = "", "", 'FILL ME'!$B$3) -> WWS | C72: =IF('FILL ME'!$B$4 = "", "", 'FILL ME'!$B$4) -> SSFLAT | D72: =TEXT('FILL ME'!$B$7,"yyyymmdd") -> 20260319 | E72: ='FILL ME'!$B$7 + 'FILL ME'!$B$11 + ('FILL ME'!$B$12 * (G72-'FILL ME'!$B$13)) -> 46100.333 | F72: =IF(A72="Grab","",TEXT(E72,"hh:mm")) -> 08:00 | I72: =CONCATENATE(H72,"_",TEXT(G72,"00")) -> _00 | J72: =CONCATENATE(C72,"_", H72,"_",D72,"_",TEXT(G72,"00")) -> SSFLAT__20260319_00 | K72: =CONCATENATE(C72,"_", H72,"_",TEXT(E72, "yyyymmdd"),"_",TEXT(F72, "hhmm")) -> SSFLAT__20260319_0800
B73: =IF('FILL ME'!$B$3 = "", "", 'FILL ME'!$B$3) -> WWS | C73: =IF('FILL ME'!$B$4 = "", "", 'FILL ME'!$B$4) -> SSFLAT | D73: =TEXT('FILL ME'!$B$7,"yyyymmdd") -> 20260319 | E73: ='FILL ME'!$B$7 + 'FILL ME'!$B$11 + ('FILL ME'!$B$12 * (G73-'FILL ME'!$B$13)) -> 46100.333 | F73: =IF(A73="Grab","",TEXT(E73,"hh:mm")) -> 08:00 | I73: =CONCATENATE(H73,"_",TEXT(G73,"00")) -> _00 | J73: =CONCATENATE(C73,"_", H73,"_",D73,"_",TEXT(G73,"00")) -> SSFLAT__20260319_00 | K73: =CONCATENATE(C73,"_", H73,"_",TEXT(E73, "yyyymmdd"),"_",TEXT(F73, "hhmm")) -> SSFLAT__20260319_0800
... B104: =IF('FILL ME'!$B$3 = "", "", 'FILL ME'!$B$3) -> WWS | C104: =IF('FILL ME'!$B$4 = "", "", 'FILL ME'!$B$4) -> SSFLAT | D104: =TEXT('FILL ME'!$B$7,"yyyymmdd") -> 20260319 | E104: ='FILL ME'!$B$7 + 'FILL ME'!$B$11 + ('FILL ME'!$B$12 * (G104-'FILL ME'!$B$13)) -> 46100.333 | F104: =IF(A104="Grab","",TEXT(E104,"hh:mm")) -> 08:00 | I104: =CONCATENATE(H104,"_",TEXT(G104,"00")) -> _00 | J104: =CONCATENATE(C104,"_", H104,"_",D104,"_",TEXT(G104,"00")) -> SSFLAT__20260319_00 | K104: =CONCATENATE(C104,"_", H104,"_",TEXT(E104, "yyyymmdd"),"_",TEXT(F104, "hhmm")) -> SSFLAT__20260319_0800
...

Sheet Bottle Numbers
A1: Separated Bottle Numbers | B1: Aqualog Bottle # | C1: Shimadzu Bottle # | D1: CCAL Bottle # | E1: Excess Bottle # | F1: Notes
A2: Sample ID | B2: (30mL/125mL Bottles) | C2: (125 mL Bottles) | D2: (125 mL Bottles) | E2: (500 mL Bottles) | F2: (any method deviations that could affect the data)
A3: {=_xlfn.CHOOSEROWS( IF('FILL ME'!B9="Bottle Number", 'Label IDs'!J:J, 'Label IDs'!K:K), _xlfn.SEQUENCE('FILL ME'!B15*'FILL ME'!B6) + 1 )} -> SSFLAT_CMP_20260319_01
A4: SSFLAT_CMP_20260319_02
A5: SSFLAT_CMP_20260319_03
A6: SSFLAT_CMP_20260319_04
A7: SSFLAT_CMP_20260319_05
A8: SSFLAT_CMP_20260319_06
A9: SSFLAT_CMP_20260319_07
A10: SSFLAT_CMP_20260319_08
A11: SSFLAT_CMP_20260319_09
A12: SSFLAT_CMP_20260319_10
A13: SSFLAT_CMP_20260319_11
A14: SSFLAT_CMP_20260319_12
A15: SSFLAT_CMP_20260319_13
... A50: SSFLAT_ALD_20260319_24

Sheet ISCO Bottle Weight
A1: ISCO Bottle Weights | B1: ISCO Bottle | D1: Notes
A2: Sample ID | B2: Pre-Weight (g) | C2: Post-Weight (g)
A3: {=_xlfn.CHOOSEROWS( IF('FILL ME'!B9="Bottle Number", 'Label IDs'!J:J, 'Label IDs'!K:K), _xlfn.SEQUENCE('FILL ME'!B15*'FILL ME'!B6) + 1 )} -> SSFLAT_CMP_20260319_01
A4: SSFLAT_CMP_20260319_02
A5: SSFLAT_CMP_20260319_03
A6: SSFLAT_CMP_20260319_04
A7: SSFLAT_CMP_20260319_05
A8: SSFLAT_CMP_20260319_06
A9: SSFLAT_CMP_20260319_07
A10: SSFLAT_CMP_20260319_08
A11: SSFLAT_CMP_20260319_09
A12: SSFLAT_CMP_20260319_10
A13: SSFLAT_CMP_20260319_11
A14: SSFLAT_CMP_20260319_12
A15: SSFLAT_CMP_20260319_13
... A50: SSFLAT_ALD_20260319_24

Sheet Filter Weight
A1: Filter Weights | B1: Filter Weight (g) | D1: Notes
A2: Sample ID | B2: Pre-Weight | C2: Post-Weight
A3: {=_xlfn.CHOOSEROWS( IF('FILL ME'!B9="Bottle Number", 'Label IDs'!J:J, 'Label IDs'!K:K), _xlfn.SEQUENCE('FILL ME'!B15*'FILL ME'!B6) + 1 )} -> SSFLAT_CMP_20260319_01
A4: SSFLAT_CMP_20260319_02
A5: SSFLAT_CMP_20260319_03
A6: SSFLAT_CMP_20260319_04
A7: SSFLAT_CMP_20260319_05
A8: SSFLAT_CMP_20260319_06
A9: SSFLAT_CMP_20260319_07
A10: SSFLAT_CMP_20260319_08
A11: SSFLAT_CMP_20260319_09
A12: SSFLAT_CMP_20260319_10
A13: SSFLAT_CMP_20260319_11
A14: SSFLAT_CMP_20260319_12
A15: SSFLAT_CMP_20260319_13
... A50: SSFLAT_ALD_20260319_24
